<?xml version="1.0" ?>
<!-- =================================================================================== -->
<!-- |    This document was autogenerated by xacro from /home/mrudula/scara_ws/src/urdf/scara_description/urdf/scara.xacro | -->
<!-- |    EDITING THIS FILE BY HAND IS NOT RECOMMENDED                                 | -->
<!-- =================================================================================== -->
<robot name="scara">
    <material name="silver">
        <color rgba="0.700 0.700 0.700 1.000" />
    </material>
    <transmission name="joint1_tran">
        <type>transmission_interface/SimpleTransmission</type>
        <joint name="joint1">
            <hardwareInterface>hardware_interface/EffortJointInterface</hardwareInterface>
        </joint>
        <actuator name="joint1_actr">
            <hardwareInterface>hardware_interface/EffortJointInterface</hardwareInterface>
            <mechanicalReduction>1</mechanicalReduction>
        </actuator>
    </transmission>
    <transmission name="joint2_tran">
        <type>transmission_interface/SimpleTransmission</type>
        <joint name="joint2">
            <hardwareInterface>hardware_interface/EffortJointInterface</hardwareInterface>
        </joint>
        <actuator name="joint2_actr">
            <hardwareInterface>hardware_interface/EffortJointInterface</hardwareInterface>
            <mechanicalReduction>1</mechanicalReduction>
        </actuator>
    </transmission>
    <transmission name="joint3_tran">
        <type>transmission_interface/SimpleTransmission</type>
        <joint name="joint3">
            <hardwareInterface>hardware_interface/EffortJointInterface</hardwareInterface>
        </joint>
        <actuator name="joint3_actr">
            <hardwareInterface>hardware_interface/EffortJointInterface</hardwareInterface>
            <mechanicalReduction>1</mechanicalReduction>
        </actuator>
    </transmission>
    <transmission name="joint4_tran">
        <type>transmission_interface/SimpleTransmission</type>
        <joint name="joint4">
            <hardwareInterface>hardware_interface/EffortJointInterface</hardwareInterface>
        </joint>
        <actuator name="joint4_actr">
            <hardwareInterface>hardware_interface/EffortJointInterface</hardwareInterface>
            <mechanicalReduction>1</mechanicalReduction>
        </actuator>
    </transmission>
    <gazebo>
        <plugin filename="libgazebo_ros_control.so" name="control" />
        <plugin name="gazebo_ros_control">
            <robotNamespace>/</robotNamespace>
        </plugin>
    </gazebo>
    <gazebo reference="base_link">
        <material>Gazebo/Silver</material>
        <mu1>0.2</mu1>
        <mu2>0.2</mu2>
        <selfCollide>true</selfCollide>
        <gravity>true</gravity>
    </gazebo>
    <gazebo reference="link1_1">
        <material>Gazebo/Silver</material>
        <mu1>0.2</mu1>
        <mu2>0.2</mu2>
        <selfCollide>true</selfCollide>
    </gazebo>
    <gazebo reference="link2_1">
        <material>Gazebo/Silver</material>
        <mu1>0.2</mu1>
        <mu2>0.2</mu2>
        <selfCollide>true</selfCollide>
    </gazebo>
    <gazebo reference="link3_1">
        <material>Gazebo/Silver</material>
        <mu1>0.2</mu1>
        <mu2>0.2</mu2>
        <selfCollide>true</selfCollide>
    </gazebo>
    <gazebo reference="tool0_1">
        <material>Gazebo/Silver</material>
        <mu1>0.2</mu1>
        <mu2>0.2</mu2>
        <selfCollide>true</selfCollide>
    </gazebo>
    <link name="base_link">
        <inertial>
            <origin rpy="0 0 0" xyz="0.12898210621867426 0.1028129499778276 0.3800243277084152" />
            <mass value="192.61152500000009" />
            <inertia ixx="12.891145" ixy="0.001045" ixz="-0.014626" iyy="13.714337" iyz="-0.017315" izz="2.144752" />
        </inertial>
        <visual>
            <origin rpy="0 0 0" xyz="0 0 0" />
            <geometry>
                <mesh filename="package://scara_description/meshes/base_link.stl" scale="0.001 0.001 0.001" />
            </geometry>
            <material name="silver" />
        </visual>
        <collision>
            <origin rpy="0 0 0" xyz="0 0 0" />
            <geometry>
                <mesh filename="package://scara_description/meshes/base_link.stl" scale="0.001 0.001 0.001" />
            </geometry>
        </collision>
    </link>
    <link name="link1_1">
        <inertial>
            <origin rpy="0 0 0" xyz="-3.7976791045224445e-07 -0.15497006523662554 0.0043939352168283485" />
            <mass value="29.47250695359581" />
            <inertia ixx="0.300227" ixy="0.0" ixz="-0.0" iyy="0.059546" iyz="0.01563" izz="0.312927" />
        </inertial>
        <visual>
            <origin rpy="0 0 0" xyz="-0.12554 -0.196237 -0.437082" />
            <geometry>
                <mesh filename="package://scara_description/meshes/link1_1.stl" scale="0.001 0.001 0.001" />
            </geometry>
            <material name="silver" />
        </visual>
        <collision>
            <origin rpy="0 0 0" xyz="-0.12554 -0.196237 -0.437082" />
            <geometry>
                <mesh filename="package://scara_description/meshes/link1_1.stl" scale="0.001 0.001 0.001" />
            </geometry>
        </collision>
    </link>
    <link name="link2_1">
        <inertial>
            <origin rpy="0 0 0" xyz="-3.7976791031346657e-07 -0.1456549328627304 -0.07795021786375345" />
            <mass value="39.847312972303484" />
            <inertia ixx="0.565311" ixy="-0.0" ixz="0.0" iyy="0.084594" iyz="-0.002335" izz="0.573499" />
        </inertial>
        <visual>
            <origin rpy="0 0 0" xyz="-0.12554 0.103763 -0.439582" />
            <geometry>
                <mesh filename="package://scara_description/meshes/link2_1.stl" scale="0.001 0.001 0.001" />
            </geometry>
            <material name="silver" />
        </visual>
        <collision>
            <origin rpy="0 0 0" xyz="-0.12554 0.103763 -0.439582" />
            <geometry>
                <mesh filename="package://scara_description/meshes/link2_1.stl" scale="0.001 0.001 0.001" />
            </geometry>
        </collision>
    </link>
    <link name="link3_1">
        <inertial>
            <origin rpy="0 0 0" xyz="-3.7976790909222125e-07 -0.14565493286273024 -0.07795021786375406" />
            <mass value="39.84731297230351" />
            <inertia ixx="0.565311" ixy="0.0" ixz="0.0" iyy="0.084594" iyz="-0.002335" izz="0.573499" />
        </inertial>
        <visual>
            <origin rpy="0 0 0" xyz="-0.12554 0.403763 -0.332582" />
            <geometry>
                <mesh filename="package://scara_description/meshes/link3_1.stl" scale="0.001 0.001 0.001" />
            </geometry>
            <material name="silver" />
        </visual>
        <collision>
            <origin rpy="0 0 0" xyz="-0.12554 0.403763 -0.332582" />
            <geometry>
                <mesh filename="package://scara_description/meshes/link3_1.stl" scale="0.001 0.001 0.001" />
            </geometry>
        </collision>
    </link>
    <link name="tool0_1">
        <inertial>
            <origin rpy="0 0 0" xyz="-3.797679083705763e-07 3.89078758655792e-07 -0.027982578325312507" />
            <mass value="1.9309956324922333" />
            <inertia ixx="0.001577" ixy="0.0" ixz="0.0" iyy="0.001577" iyz="0.0" izz="0.002667" />
        </inertial>
        <visual>
            <origin rpy="0 0 0" xyz="-0.12554 0.703763 -0.225582" />
            <geometry>
                <mesh filename="package://scara_description/meshes/tool0_1.stl" scale="0.001 0.001 0.001" />
            </geometry>
            <material name="silver" />
        </visual>
        <collision>
            <origin rpy="0 0 0" xyz="-0.12554 0.703763 -0.225582" />
            <geometry>
                <mesh filename="package://scara_description/meshes/tool0_1.stl" scale="0.001 0.001 0.001" />
            </geometry>
        </collision>
    </link>
    <joint name="joint1" type="prismatic">
        <origin rpy="0 0 0" xyz="0.12554 0.196237 0.437082" />
        <parent link="base_link" />
        <child link="link1_1" />
        <axis xyz="0.0 -0.0 1.0" />
        <limit effort="100" lower="-0.1" upper="0.265" velocity="100" />
    </joint>
    <joint name="joint2" type="revolute">
        <origin rpy="0 0 0" xyz="0.0 -0.3 0.0025" />
        <parent link="link1_1" />
        <child link="link2_1" />
        <axis xyz="0.0 0.0 -1.0" />
        <limit effort="100" lower="-1.745329" upper="1.745329" velocity="100" />
    </joint>
    <joint name="joint3" type="revolute">
        <origin rpy="0 0 0" xyz="0.0 -0.3 -0.107" />
        <parent link="link2_1" />
        <child link="link3_1" />
        <axis xyz="0.0 0.0 -1.0" />
        <limit effort="100" lower="-2.356194" upper="2.356194" velocity="100" />
    </joint>
    <joint name="joint4" type="revolute">
        <origin rpy="0 0 0" xyz="0.0 -0.3 -0.107" />
        <parent link="link3_1" />
        <child link="tool0_1" />
        <axis xyz="0.0 0.0 -1.0" />
        <limit effort="100" lower="-2.617994" upper="2.617994" velocity="100" />
    </joint>
    <link name="world" />
    <joint name="world_to_base_link" type="fixed">
        <parent link="world" />
        <child link="base_link" />
        <origin rpy="0 0 0" xyz="0 0 0" />
    </joint>
</robot>

